<?xml version="1.0"?>
<robot xmlns:sensor="http://playerstage.sourceforge.net/gazebo/xmlschema/#sensor"
       xmlns:controller="http://playerstage.sourceforge.net/gazebo/xmlschema/#controller"
       xmlns:interface="http://playerstage.sourceforge.net/gazebo/xmlschema/#interface">

  <include filename="$(find kuka_lwr_description)/urdf/common/util_defs.xml"/>

  <property name="arm_elem_base_mass" value="2.0"/>
  <property name="arm_elem_link_mass" value="2.0"/>
  <property name="arm_elem_ball_link_mass" value="2.0"/>
  <property name="arm_elem_end_link_mass" value="2.0"/>
  <property name="safety_controller_k_pos" value="100" />
  <property name="safety_controller_k_vel" value="2" />
  <property name="joint_damping" value="0.1" />

  <property name="arm_velocity_scale_factor" value="1"/>

  <!-- right is either 1 (for right arm) or -1 (for left arm) -->
  <macro name="kuka_lwr_arm" params="parent name right tool_name *origin">

    <joint name="${parent}_${name}_arm_base_joint" type="fixed">
      <insert_block name="origin"/>
      <parent link="${parent}"/>
      <child link="calib_${name}_arm_base_link"/>
    </joint>

    <link name="calib_${name}_arm_base_link">
      <inertial>
        <mass value="${arm_elem_base_mass}"/>
        <origin xyz="0 0 0.055" rpy="0 0 0"/>
        <cylinder_inertia_def radius="0.06" length="0.11"
                              mass="${arm_elem_base_mass}"/>
      </inertial>

      <visual>
        <origin xyz="0 0 0" rpy="0 0 0"/>
        <geometry>
          <mesh filename="package://kuka_lwr_description/meshes/arm/arm_base.stl"/>
        </geometry>
        <material name="Orange"/>
      </visual>
      <collision>
        <origin xyz="0 0 0" rpy="0 0 0"/>
        <geometry>
          <mesh filename="package://kuka_lwr_description/meshes/arm/convex/arm_base_convex.stl"/>
        </geometry>
      </collision>
    </link>

    <gazebo reference="calib_${name}_arm_base_link">
      <material value="kuka-lwr.material"/>
    </gazebo>

    <joint name="${name}_arm_joint_0" type="revolute">
      <origin xyz="0 0 0.11" rpy="0 0 0"/>
      <axis xyz="0 0 1"/>
      <limit lower="${-170 * M_PI / 180}" upper="${170 * M_PI / 180}"
             effort="204" velocity="${arm_velocity_scale_factor * 110 * M_PI / 180}" />
      <safety_controller soft_lower_limit="${-168 * M_PI / 180}"
                         soft_upper_limit="${168 * M_PI / 180}"
                         k_position="${safety_controller_k_pos}"
                         k_velocity="${safety_controller_k_vel}"/>
      <dynamics damping="${joint_damping}"/>
      <parent link="calib_${name}_arm_base_link"/>
      <child link="${name}_arm_link_1"/>
    </joint>

    <link name="${name}_arm_link_1">
      <inertial>
        <mass value="${arm_elem_link_mass}"/>
        <origin rpy="0 0 0" xyz="0 0 0.130"/>
        <cuboid_inertia_def length="0.12" width="0.06" height="0.260"
                            mass="${arm_elem_link_mass}"/>
      </inertial>

      <visual>
        <origin xyz="0 0 0" rpy="0 0 ${M_PI}"/>
        <geometry>
          <mesh filename="package://kuka_lwr_description/meshes/arm/arm_segment_a.stl"/>
        </geometry>
        <material name="Orange"/>
      </visual>

      <collision>
        <origin xyz="0 0 0" rpy="0 0 ${M_PI}"/>
        <geometry>
          <mesh filename="package://kuka_lwr_description/meshes/arm/convex/arm_segment_a_convex.stl"/>
        </geometry>
      </collision>
    </link>

    <gazebo reference="${name}_arm_link_1">
      <material value="kuka-lwr.material"/>
    </gazebo>

    <transmission name="${name}_arm_trans_0" type="pr2_mechanism_model/SimpleTransmission">
      <actuator name="${name}_arm_motor_0"/>
      <joint name="${name}_arm_joint_0"/>
      <mechanicalReduction>1.0</mechanicalReduction>
    </transmission>

    <joint name="${name}_arm_joint_1" type="revolute">
      <origin xyz="0 0 0.20" rpy="0 0 0"/>
      <axis xyz="0 -1 0"/>
      <limit lower="${-120 * M_PI / 180}" upper="${120 * M_PI / 180}"
             effort="306" velocity="${arm_velocity_scale_factor * 110 * M_PI / 180}" />
      <safety_controller soft_lower_limit="${-118 * M_PI / 180}"
                         soft_upper_limit="${118 * M_PI / 180}"
                         k_position="${safety_controller_k_pos}"
                         k_velocity="${safety_controller_k_vel}"/>
      <dynamics damping="${joint_damping}"/>
      <parent link="${name}_arm_link_1"/>
      <child link="${name}_arm_link_2"/>
    </joint>

    <link name="${name}_arm_link_2">
      <inertial>
        <mass value="${arm_elem_link_mass}"/>
        <origin rpy="0 0 0" xyz="0 0.06 ${0.130 - 0.06}"/>
        <cuboid_inertia_def length="0.12" width="0.06" height="0.260"
                            mass="${arm_elem_link_mass}"/>
      </inertial>

      <visual>
        <origin xyz="0 0 0.2" rpy="${M_PI} 0 ${M_PI}"/>
        <geometry>
          <mesh filename="package://kuka_lwr_description/meshes/arm/arm_segment_b.stl"/>
        </geometry>
        <material name="Orange"/>
      </visual>

      <collision>
        <origin xyz="0 0 0.2" rpy="${M_PI} 0 ${M_PI}"/>
        <geometry>
          <mesh filename="package://kuka_lwr_description/meshes/arm/convex/arm_segment_b_convex.stl"/>
        </geometry>
      </collision>
    </link>

    <gazebo reference="${name}_arm_link_2">
      <material value="kuka-lwr.material"/>
    </gazebo>

    <transmission name="${name}_arm_trans_1" type="pr2_mechanism_model/SimpleTransmission">
      <actuator name="${name}_arm_motor_1"/>
      <joint name="${name}_arm_joint_1"/>
      <mechanicalReduction>1.0</mechanicalReduction>
    </transmission>

    <joint name="${name}_arm_joint_2" type="revolute">
      <origin xyz="0 0 0.20" rpy="0 0 0"/>
      <axis xyz="0 0 1"/>
      <limit lower="${-170 * M_PI / 180}" upper="${170 * M_PI / 180}"
             effort="204" velocity="${arm_velocity_scale_factor * 130 * M_PI / 180}" />
      <safety_controller soft_lower_limit="${-168 * M_PI / 180}"
                         soft_upper_limit="${168 * M_PI / 180}"
                         k_position="${safety_controller_k_pos}"
                         k_velocity="${safety_controller_k_vel}"/>
      <dynamics damping="${joint_damping}"/>
      <parent link="${name}_arm_link_2"/>
      <child link="${name}_arm_link_3"/>
    </joint>

    <link name="${name}_arm_link_3">
      <inertial>
        <mass value="${arm_elem_link_mass}"/>
        <origin rpy="0 0 0" xyz="0 0.06 0.130"/>
        <cuboid_inertia_def length="0.12" width="0.06" height="0.260"
                            mass="${arm_elem_link_mass}"/>
      </inertial>

      <visual>
        <origin xyz="0 0 0" rpy="0 0 0"/>
        <geometry>
          <mesh filename="package://kuka_lwr_description/meshes/arm/arm_segment_a.stl"/>
        </geometry>
        <material name="Orange"/>
      </visual>

      <collision>
        <origin xyz="0 0 0" rpy="0 0 0"/>
        <geometry>
          <mesh filename="package://kuka_lwr_description/meshes/arm/convex/arm_segment_a_convex.stl"/>
        </geometry>
      </collision>
    </link>

    <gazebo reference="${name}_arm_link_3">
      <material value="kuka-lwr.material"/>
    </gazebo>

    <transmission name="${name}_arm_trans_2" type="pr2_mechanism_model/SimpleTransmission">
      <actuator name="${name}_arm_motor_2"/>
      <joint name="${name}_arm_joint_2"/>
      <mechanicalReduction>1.0</mechanicalReduction>
    </transmission>

    <joint name="${name}_arm_joint_3" type="revolute">
      <origin xyz="0 0 0.20" rpy="0 0 0"/>
      <axis xyz="0 1 0"/>
      <limit lower="${-120 * M_PI / 180}" upper="${120 * M_PI / 180}"
             effort="306" velocity="${arm_velocity_scale_factor * 130 * M_PI / 180}" />
      <safety_controller soft_lower_limit="${-118 * M_PI / 180}"
                         soft_upper_limit="${118 * M_PI / 180}"
                         k_position="${safety_controller_k_pos}"
                         k_velocity="${safety_controller_k_vel}"/>
      <dynamics damping="${joint_damping}"/>
      <parent link="${name}_arm_link_3"/>
      <child link="${name}_arm_link_4"/>
    </joint>

    <link name="${name}_arm_link_4">
      <inertial>
        <mass value="${arm_elem_link_mass}"/>
        <origin rpy="0 0 0" xyz="0 -0.06 ${0.130 - 0.06}"/>
        <cuboid_inertia_def length="0.12" width="0.06" height="0.2600"
                            mass="${arm_elem_link_mass}"/>
      </inertial>

      <visual>
        <origin xyz="0 0 0.2" rpy="0 ${M_PI} ${M_PI}"/>
        <geometry>
          <mesh filename="package://kuka_lwr_description/meshes/arm/arm_segment_b.stl"/>
        </geometry>
        <material name="Orange"/>
      </visual>

      <collision>
        <origin xyz="0 0 0.2" rpy="0 ${M_PI} ${M_PI}"/>
        <geometry>
          <mesh filename="package://kuka_lwr_description/meshes/arm/convex/arm_segment_b_convex.stl"/>
        </geometry>
      </collision>
    </link>

    <gazebo reference="${name}_arm_link_4">
      <material value="kuka-lwr.material"/>
    </gazebo>

    <transmission name="${name}_arm_trans_3" type="pr2_mechanism_model/SimpleTransmission">
      <actuator name="${name}_arm_motor_3"/>
      <joint name="${name}_arm_joint_3"/>
      <mechanicalReduction>1.0</mechanicalReduction>
    </transmission>

    <joint name="${name}_arm_joint_4" type="revolute">
      <origin xyz="0 0 0.20" rpy="0 0 0"/>
      <axis xyz="0 0 1"/>
      <limit lower="${-170 * M_PI / 180}" upper="${170 * M_PI / 180}"
             effort="204" velocity="${arm_velocity_scale_factor * 130 * M_PI / 180}" />
      <safety_controller soft_lower_limit="${-168 * M_PI / 180}"
                         soft_upper_limit="${168 * M_PI / 180}"
                         k_position="${safety_controller_k_pos}"
                         k_velocity="${safety_controller_k_vel}"/>
      <dynamics damping="${joint_damping}"/>
      <parent link="${name}_arm_link_4"/>
      <child link="${name}_arm_link_5"/>
    </joint>

    <link name="${name}_arm_link_5">
      <inertial>
        <mass value="${arm_elem_link_mass}"/>
        <origin rpy="0 0 0" xyz="0 0 0.124"/>
        <cuboid_inertia_def length="0.12" width="0.06" height="0.248"
                            mass="${arm_elem_link_mass}"/>
      </inertial>

      <visual>
        <origin xyz="0 0 0" rpy="0 0 ${M_PI}"/>
        <geometry name="${name}_arm_5_geom">
          <mesh filename="package://kuka_lwr_description/meshes/arm/arm_segment_last.stl"/>
        </geometry>
        <material name="Orange"/>
      </visual>

      <collision>
        <origin xyz="0 0 0" rpy="0 0 ${M_PI}"/>
        <geometry>
          <mesh filename="package://kuka_lwr_description/meshes/arm/convex/arm_segment_last_convex.stl"/>
        </geometry>
      </collision>
    </link>

    <gazebo reference="${name}_arm_link_5">
      <material value="kuka-lwr.material"/>
    </gazebo>

    <transmission name="${name}_arm_trans_4" type="pr2_mechanism_model/SimpleTransmission">
      <actuator name="${name}_arm_motor_4"/>
      <joint name="${name}_arm_joint_4"/>
      <mechanicalReduction>1.0</mechanicalReduction>
    </transmission>

    <joint name="${name}_arm_joint_5" type="revolute">
      <origin xyz="0 0 0.19" rpy="0 0 0"/>
      <axis xyz="0 -1 0"/>
      <limit lower="${-120 * M_PI / 180}" upper="${120 * M_PI / 180}"
             effort="306" velocity="${arm_velocity_scale_factor * 180 * M_PI / 180}" />
      <safety_controller soft_lower_limit="${-118 * M_PI / 180}"
                         soft_upper_limit="${118 * M_PI / 180}"
                         k_position="${safety_controller_k_pos}"
                         k_velocity="${safety_controller_k_vel}"/>
      <dynamics damping="${joint_damping}"/>
      <parent link="${name}_arm_link_5"/>
      <child link="${name}_arm_link_6"/>
    </joint>

    <link name="${name}_arm_link_6">
      <inertial>
        <mass value="${arm_elem_ball_link_mass}"/>
        <origin rpy="0 0 0" xyz="0 0 0.0625"/>
        <cuboid_inertia_def length="0.125" width="0.125" height="0.125"
                            mass="${arm_elem_ball_link_mass}"/>
      </inertial>

      <visual>
        <origin xyz="0 0 0" rpy="0 0 ${M_PI}"/>
        <geometry>
          <mesh filename="package://kuka_lwr_description/meshes/arm/arm_wrist.stl"/>
        </geometry>
        <material name="Grey"/>
      </visual>

      <collision>
        <origin xyz="0 0 0" rpy="0 0 ${M_PI}"/>
        <geometry>
          <mesh filename="package://kuka_lwr_description/meshes/arm/convex/arm_wrist_convex.stl"/>
        </geometry>
      </collision>
    </link>

    <gazebo reference="${name}_arm_link_6">
      <material value="kuka-lwr.material"/>
    </gazebo>

    <transmission name="${name}_arm_trans_5" type="pr2_mechanism_model/SimpleTransmission">
      <actuator name="${name}_arm_motor_5"/>
      <joint name="${name}_arm_joint_5"/>
      <mechanicalReduction>1.0</mechanicalReduction>
    </transmission>

    <joint name="${name}_arm_joint_6" type="revolute">
      <origin xyz="0 0 0.078" rpy="0 0 0"/>
      <axis xyz="0 0 1"/>
      <limit lower="${-170 * M_PI / 180}" upper="${170 * M_PI / 180}"
             effort="204" velocity="${arm_velocity_scale_factor * 180 * M_PI / 180}" />
      <safety_controller soft_lower_limit="${-168 * M_PI / 180}"
                         soft_upper_limit="${168 * M_PI / 180}"
                         k_position="${safety_controller_k_pos}"
                         k_velocity="${safety_controller_k_vel}"/>
      <dynamics damping="${joint_damping}"/>
      <parent link="${name}_arm_link_6"/>
      <child link="${name}_arm_link_7"/>
    </joint>


    <link name="${name}_arm_link_7">
<visual>
	<origin xyz="0 0 -0.02" rpy="0 0 0" />
		<geometry>
			<mesh filename="package://cob_description/meshes/lbr/joint_7.stl" />
		</geometry>
		<material name="grey">
       			<color rgba="0.5 0.5 0.5 0.8"/>
       		</material>   

	</visual>
      <inertial>
        <mass value="${arm_elem_end_link_mass}"/>
        <origin xyz="0 0 0"/>
        <cuboid_inertia_def length="1" width="1" height="1"
                            mass="${arm_elem_end_link_mass}"/>
      </inertial>
    </link>


    <transmission name="${name}_arm_trans_6" type="pr2_mechanism_model/SimpleTransmission">
      <actuator name="${name}_arm_motor_6"/>
      <joint name="${name}_arm_joint_6"/>
      <mechanicalReduction>1.0</mechanicalReduction>
    </transmission>
    


  </macro>

</robot>
